<!-- ======================================================

  This model has been modified and also include:
  - position and velocity actuators
  - multiple cameras
  - virtual target

  Author    :: Feryal M P Behbahani

  Original model from: http://mujoco.org/forum/index.php?resources/kinova-arms.12/

    This file is part of MuJoCo.
    Copyright 2009-2016 Roboti LLC.

    Model     :: Jaco Arm from Kinova Robotics
      Source    : www.github.com/Kinovarobotics
      Downloaded  : July 25, 2015

    Mujoco    :: Advanced physics simulation engine
      Source    : www.roboti.us
      Version   : 1.31
      Released  : 23Apr16

    Author    :: Vikash Kumar
      Contacts  : kumar@roboti.us
      Last edits  : 30Apr16, 30Nov15, 26Sept'15, 26July'15

====================================================== -->

<mujoco model="pushing">
  <compiler inertiafromgeom='true' angle="radian" meshdir="meshes/" />

  <option integrator="RK4" solver="PGS" timestep="0.001" gravity="0 0 -9.81" iterations="50"/>

  <asset>
    <mesh file="pushing_box.stl"/>
    <mesh file="pushing_hand.stl"/>


    <texture type="skybox" builtin="gradient" rgb1=".2 .3 .4" rgb2="1 1 1"
      width="100" height="100"/>
    <texture name="groundplane" type="2d" builtin="checker" rgb1=".25 .26 .25"
      rgb2=".22 .22 .22" width="100" height="100" mark="none" markrgb=".8 .8 .8"/>
    <texture name="greenground" type="2d" builtin="gradient" rgb1="0.19 0.28 0.23"
      rgb2="0 0 0" width="100" height="100" mark="none" markrgb=".8 .8 .8"/>
    <material name="MatViz" specular="1" shininess=".1" reflectance="0.5" rgba=".07 .07 .1 1"/>
    <material name="MatGnd" texture="groundplane"  texrepeat="5 5" specular="1" shininess="0" reflectance="0"/>


  </asset>

  <default>
    <geom contype='1' conaffinity='1' condim='3' margin="0.001" />

    <joint limited="false" damping="0" armature=".01"/>

    <default class ="vizNcoll">
      <geom material="MatViz" type="mesh" condim="3" contype="1" conaffinity="1" margin="0.001"/>
      <joint pos="0 0 0" type="hinge"/>
    </default>
    <default class ="ground">
      <geom type="plane" margin="0.001" contype="1" />
    </default>
  </default>

  <worldbody>

    <light cutoff="200" diffuse="1.2 1.2 1.2" dir="-0 0 -1.3" directional="true" exponent="1" pos="0 0 1.3" specular=".1 .1 .1"/>

    <camera name="view1" pos="0 0 2.0" zaxis="0 0 1" fovy="45" ipd="0.068"/>
    <camera name="view2" pos="1.0 0.7 0.3" xyaxes="-1 1 0 0 0 1" fovy="45" ipd="0.068"/>


    <geom name="ground" class="ground" type='plane' pos="0 0 0" rgba="0.19 0.30 0.23 1" size="2 2 1"/>

    <body name="pushing_box" childclass="vizNcoll" pos="0 0 0.25">
      <geom mesh="pushing_box"/>
      <body name="pushing_hand_1" childclass="vizNcoll" pos="0 0 0.25">
          <joint axis="1 0 0" limited="true" name="slider" pos="0 0 0" range="-1 1" type="slide"/>
          <geom mesh="pushing_hand"/>
      </body>

    </body>
    
    <geom name="target" pos="0.6 0.3 0.3" rgba="0.9 0.2 0.2 1" size=".05" type="sphere" contype='0' conaffinity="0"/>


  </worldbody>

    <!--  ================= Torque actuators (Weren't present in the URDF. Added seperately)================= /-->
<!--
  <actuator>
    <motor joint='jaco_joint_1'   name='Ajaco_joint_1' gear="50" ctrlrange='-3.141 3.141' ctrllimited='true'/>
    <motor joint='jaco_joint_2'   name='Ajaco_joint_2' gear="100" ctrlrange='-2.40855 2.40855' ctrllimited='true'/>
    <motor joint='jaco_joint_3'   name='Ajaco_joint_3' gear="100" ctrlrange='-2.84489 2.84489' ctrllimited='true'/>
    <motor joint='jaco_joint_4'   name='Ajaco_joint_4' gear="50" ctrlrange='-3.141 3.141' ctrllimited='true'/>
    <motor joint='jaco_joint_5'   name='Ajaco_joint_5' gear="50" ctrlrange='-3.141 3.141' ctrllimited='true'/>
    <motor joint='jaco_joint_6'   name='Ajaco_joint_6' gear="50" ctrlrange='-3.141 3.141' ctrllimited='true'/>
    <motor joint='jaco_joint_finger_1'  name='Ajaco_joint_finger_1' gear='10'/>
    <motor joint='jaco_joint_finger_2'  name='Ajaco_joint_finger_2' gear='10'/>
    <motor joint='jaco_joint_finger_3'  name='Ajaco_joint_finger_3' gear='10'/>
  </actuator>
/-->


    <!--  ================= Position actuators ================= /-->
<!--   <actuator>
    <position joint='jaco_joint_1'  name='Ajaco_joint_1' kp="50" ctrlrange='-3.141 3.141' ctrllimited='true'/>
    <position joint='jaco_joint_2'  name='Ajaco_joint_2' kp="100" ctrlrange='-2.40855 2.40855' ctrllimited='true'/>
    <position joint='jaco_joint_3'  name='Ajaco_joint_3' kp="100" ctrlrange='-2.84489 2.84489' ctrllimited='true'/>
    <position joint='jaco_joint_4'  name='Ajaco_joint_4' kp="50" ctrlrange='-3.141 3.141' ctrllimited='true'/>
    <position joint='jaco_joint_5'  name='Ajaco_joint_5' kp="50" ctrlrange='-3.141 3.141' ctrllimited='true'/>
    <position joint='jaco_joint_6'  name='Ajaco_joint_6' kp="50" ctrlrange='-3.141 3.141' ctrllimited='true'/>
  </actuator>
 -->

    <!--  ================= Velocity actuators ================= /-->
  <actuator>
      <motor gear="100" joint="slider" name="slide"/>
  </actuator>

</mujoco>
